Workbook

Sheet Products
A1: Product List & Pricing
A2: Fill in every product you sell. Yellow cells = your input. Delete the example rows once you've added your own products.
A4: Product Name | B4: Category | C4: Cost Price (per unit) | D4: Selling Price (per unit) | E4: Profit per Unit | F4: Current Stock (units)
A5: 9PM | B5: OIL | C5: 2500 | D5: 5000 | E5: =D5-C5 -> 2500 | F5: 8
A6: KAYALI VANILLA | B6: OIL | C6: 2500 | D6: 5000 | E6: =D6-C6 -> 2500 | F6: 4
A7: CHOCOLATE | B7: OIL | C7: 2500 | D7: 5000 | E7: =D7-C7 -> 2500 | F7: 2
A8: STRAWBERRY | B8: OIL | C8: 2500 | D8: 5000 | E8: =D8-C8 -> 2500 | F8: 2
A9: YUMMY VANILLA | B9: OIL | C9: 2500 | D9: 5000 | E9: =D9-C9 -> 2500 | F9: 3
A10: CLUB DE NUIT | B10: OIL | C10: 2500 | D10: 5000 | E10: =D10-C10 -> 2500 | F10: 2
E11: =D11-C11 -> 0 | F11: 2
E21: =IF(D21="","",D21-C21)
E22: =IF(D22="","",D22-C22)
E23: =IF(D23="","",D23-C23)
E24: =IF(D24="","",D24-C24)
E25: =IF(D25="","",D25-C25)
E26: =IF(D26="","",D26-C26)
E27: =IF(D27="","",D27-C27)
E28: =IF(D28="","",D28-C28)
E29: =IF(D29="","",D29-C29)
E30: =IF(D30="","",D30-C30)
E31: =IF(D31="","",D31-C31)
E32: =IF(D32="","",D32-C32)
... E51: =IF(D51="","",D51-C51)

Sheet Sales Log
A1: Sales Log
A2: Enter the Date, Product and Quantity Sold for each sale (yellow cells). Price, cost and profit fill in automatically from the Products sheet.
A4: Date | B4: Product | C4: Quantity Sold | D4: Unit Selling Price | E4: Unit Cost | F4: Total Revenue | G4: Total Cost | H4: Profit
A5: 46226 | B5: CHOCOLATE | C5: 2 | D5: =IF($B5="","",IFERROR(INDEX(Products!$D$5:$D$51,MATCH($B5,Products!$A$5:$A$51,0)),"")) -> 5000 | E5: =IF($B5="","",IFERROR(INDEX(Products!$C$5:$C$51,MATCH($B5,Products!$A$5:$A$51,0)),"")) -> 2500 | F5: =IF($B5="","",$C5*$D5) -> 10000 | G5: =IF($B5="","",$C5*$E5) -> 5000 | H5: =IF($B5="","",$F5-$G5) -> 5000
D6: =IF($B6="","",IFERROR(INDEX(Products!$D$5:$D$51,MATCH($B6,Products!$A$5:$A$51,0)),"")) | E6: =IF($B6="","",IFERROR(INDEX(Products!$C$5:$C$51,MATCH($B6,Products!$A$5:$A$51,0)),"")) | F6: =IF($B6="","",$C6*$D6) | G6: =IF($B6="","",$C6*$E6) | H6: =IF($B6="","",$F6-$G6)
D7: =IF($B7="","",IFERROR(INDEX(Products!$D$5:$D$51,MATCH($B7,Products!$A$5:$A$51,0)),"")) | E7: =IF($B7="","",IFERROR(INDEX(Products!$C$5:$C$51,MATCH($B7,Products!$A$5:$A$51,0)),"")) | F7: =IF($B7="","",$C7*$D7) | G7: =IF($B7="","",$C7*$E7) | H7: =IF($B7="","",$F7-$G7)
D8: =IF($B8="","",IFERROR(INDEX(Products!$D$5:$D$51,MATCH($B8,Products!$A$5:$A$51,0)),"")) | E8: =IF($B8="","",IFERROR(INDEX(Products!$C$5:$C$51,MATCH($B8,Products!$A$5:$A$51,0)),"")) | F8: =IF($B8="","",$C8*$D8) | G8: =IF($B8="","",$C8*$E8) | H8: =IF($B8="","",$F8-$G8)
D9: =IF($B9="","",IFERROR(INDEX(Products!$D$5:$D$51,MATCH($B9,Products!$A$5:$A$51,0)),"")) | E9: =IF($B9="","",IFERROR(INDEX(Products!$C$5:$C$51,MATCH($B9,Products!$A$5:$A$51,0)),"")) | F9: =IF($B9="","",$C9*$D9) | G9: =IF($B9="","",$C9*$E9) | H9: =IF($B9="","",$F9-$G9)
D10: =IF($B10="","",IFERROR(INDEX(Products!$D$5:$D$51,MATCH($B10,Products!$A$5:$A$51,0)),"")) | E10: =IF($B10="","",IFERROR(INDEX(Products!$C$5:$C$51,MATCH($B10,Products!$A$5:$A$51,0)),"")) | F10: =IF($B10="","",$C10*$D10) | G10: =IF($B10="","",$C10*$E10) | H10: =IF($B10="","",$F10-$G10)
D11: =IF($B11="","",IFERROR(INDEX(Products!$D$5:$D$51,MATCH($B11,Products!$A$5:$A$51,0)),"")) | E11: =IF($B11="","",IFERROR(INDEX(Products!$C$5:$C$51,MATCH($B11,Products!$A$5:$A$51,0)),"")) | F11: =IF($B11="","",$C11*$D11) | G11: =IF($B11="","",$C11*$E11) | H11: =IF($B11="","",$F11-$G11)
D12: =IF($B12="","",IFERROR(INDEX(Products!$D$5:$D$51,MATCH($B12,Products!$A$5:$A$51,0)),"")) | E12: =IF($B12="","",IFERROR(INDEX(Products!$C$5:$C$51,MATCH($B12,Products!$A$5:$A$51,0)),"")) | F12: =IF($B12="","",$C12*$D12) | G12: =IF($B12="","",$C12*$E12) | H12: =IF($B12="","",$F12-$G12)
D13: =IF($B13="","",IFERROR(INDEX(Products!$D$5:$D$51,MATCH($B13,Products!$A$5:$A$51,0)),"")) | E13: =IF($B13="","",IFERROR(INDEX(Products!$C$5:$C$51,MATCH($B13,Products!$A$5:$A$51,0)),"")) | F13: =IF($B13="","",$C13*$D13) | G13: =IF($B13="","",$C13*$E13) | H13: =IF($B13="","",$F13-$G13)
D14: =IF($B14="","",IFERROR(INDEX(Products!$D$5:$D$51,MATCH($B14,Products!$A$5:$A$51,0)),"")) | E14: =IF($B14="","",IFERROR(INDEX(Products!$C$5:$C$51,MATCH($B14,Products!$A$5:$A$51,0)),"")) | F14: =IF($B14="","",$C14*$D14) | G14: =IF($B14="","",$C14*$E14) | H14: =IF($B14="","",$F14-$G14)
D15: =IF($B15="","",IFERROR(INDEX(Products!$D$5:$D$51,MATCH($B15,Products!$A$5:$A$51,0)),"")) | E15: =IF($B15="","",IFERROR(INDEX(Products!$C$5:$C$51,MATCH($B15,Products!$A$5:$A$51,0)),"")) | F15: =IF($B15="","",$C15*$D15) | G15: =IF($B15="","",$C15*$E15) | H15: =IF($B15="","",$F15-$G15)
D16: =IF($B16="","",IFERROR(INDEX(Products!$D$5:$D$51,MATCH($B16,Products!$A$5:$A$51,0)),"")) | E16: =IF($B16="","",IFERROR(INDEX(Products!$C$5:$C$51,MATCH($B16,Products!$A$5:$A$51,0)),"")) | F16: =IF($B16="","",$C16*$D16) | G16: =IF($B16="","",$C16*$E16) | H16: =IF($B16="","",$F16-$G16)
D17: =IF($B17="","",IFERROR(INDEX(Products!$D$5:$D$51,MATCH($B17,Products!$A$5:$A$51,0)),"")) | E17: =IF($B17="","",IFERROR(INDEX(Products!$C$5:$C$51,MATCH($B17,Products!$A$5:$A$51,0)),"")) | F17: =IF($B17="","",$C17*$D17) | G17: =IF($B17="","",$C17*$E17) | H17: =IF($B17="","",$F17-$G17)
... D300: =IF($B300="","",IFERROR(INDEX(Products!$D$5:$D$51,MATCH($B300,Products!$A$5:$A$51,0)),"")) | E300: =IF($B300="","",IFERROR(INDEX(Products!$C$5:$C$51,MATCH($B300,Products!$A$5:$A$51,0)),"")) | F300: =IF($B300="","",$C300*$D300) | G300: =IF($B300="","",$C300*$E300) | H300: =IF($B300="","",$F300-$G300)
B302: TOTAL | C302: =SUM(C5:C300) -> 2 | F302: =SUM(F5:F300) -> 10000 | G302: =SUM(G5:G300) -> 5000 | H302: =SUM(H5:H300) -> 5000

Sheet Dashboard
A1: Business Dashboard
A2: Auto-calculated from the Sales Log. Nothing to fill in here.
A4: Overall Totals
A5: Total Revenue | B5: ='Sales Log'!F302 -> 10000
A6: Total Cost | B6: ='Sales Log'!G302 -> 5000
A7: Total Profit | B7: ='Sales Log'!H302 -> 5000
A8: Profit Margin (%) | B8: =IF(B5=0,0,B7/B5) -> 0.5
A11: Sales by Product
A12: Product | B12: Units Sold | C12: Revenue | D12: Cost | E12: Profit
A13: =IF(Products!$A$5="","",Products!$A$5) -> 9PM | B13: =IF(Products!$A$5="","",SUMIFS('Sales Log'!$C$5:$C$300,'Sales Log'!$B$5:$B$300,Products!$A$5)) -> 0 | C13: =IF(Products!$A$5="","",SUMIFS('Sales Log'!$F$5:$F$300,'Sales Log'!$B$5:$B$300,Products!$A$5)) -> 0 | D13: =IF(Products!$A$5="","",SUMIFS('Sales Log'!$G$5:$G$300,'Sales Log'!$B$5:$B$300,Products!$A$5)) -> 0 | E13: =IF(Products!$A$5="","",SUMIFS('Sales Log'!$H$5:$H$300,'Sales Log'!$B$5:$B$300,Products!$A$5)) -> 0
A14: =IF(Products!$A$7="","",Products!$A$7) -> CHOCOLATE | B14: =IF(Products!$A$7="","",SUMIFS('Sales Log'!$C$5:$C$300,'Sales Log'!$B$5:$B$300,Products!$A$7)) -> 2 | C14: =IF(Products!$A$7="","",SUMIFS('Sales Log'!$F$5:$F$300,'Sales Log'!$B$5:$B$300,Products!$A$7)) -> 10000 | D14: =IF(Products!$A$7="","",SUMIFS('Sales Log'!$G$5:$G$300,'Sales Log'!$B$5:$B$300,Products!$A$7)) -> 5000 | E14: =IF(Products!$A$7="","",SUMIFS('Sales Log'!$H$5:$H$300,'Sales Log'!$B$5:$B$300,Products!$A$7)) -> 5000
A15: =IF(Products!$A$10="","",Products!$A$10) -> CLUB DE NUIT | B15: =IF(Products!$A$10="","",SUMIFS('Sales Log'!$C$5:$C$300,'Sales Log'!$B$5:$B$300,Products!$A$10)) -> 0 | C15: =IF(Products!$A$10="","",SUMIFS('Sales Log'!$F$5:$F$300,'Sales Log'!$B$5:$B$300,Products!$A$10)) -> 0 | D15: =IF(Products!$A$10="","",SUMIFS('Sales Log'!$G$5:$G$300,'Sales Log'!$B$5:$B$300,Products!$A$10)) -> 0 | E15: =IF(Products!$A$10="","",SUMIFS('Sales Log'!$H$5:$H$300,'Sales Log'!$B$5:$B$300,Products!$A$10)) -> 0
A16: =IF(Products!$A$13="","",Products!$A$13) | B16: =IF(Products!$A$13="","",SUMIFS('Sales Log'!$C$5:$C$300,'Sales Log'!$B$5:$B$300,Products!$A$13)) | C16: =IF(Products!$A$13="","",SUMIFS('Sales Log'!$F$5:$F$300,'Sales Log'!$B$5:$B$300,Products!$A$13)) | D16: =IF(Products!$A$13="","",SUMIFS('Sales Log'!$G$5:$G$300,'Sales Log'!$B$5:$B$300,Products!$A$13)) | E16: =IF(Products!$A$13="","",SUMIFS('Sales Log'!$H$5:$H$300,'Sales Log'!$B$5:$B$300,Products!$A$13))
A17: =IF(Products!$A$20="","",Products!$A$20) | B17: =IF(Products!$A$20="","",SUMIFS('Sales Log'!$C$5:$C$300,'Sales Log'!$B$5:$B$300,Products!$A$20)) | C17: =IF(Products!$A$20="","",SUMIFS('Sales Log'!$F$5:$F$300,'Sales Log'!$B$5:$B$300,Products!$A$20)) | D17: =IF(Products!$A$20="","",SUMIFS('Sales Log'!$G$5:$G$300,'Sales Log'!$B$5:$B$300,Products!$A$20)) | E17: =IF(Products!$A$20="","",SUMIFS('Sales Log'!$H$5:$H$300,'Sales Log'!$B$5:$B$300,Products!$A$20))
A18: =IF(Products!$A$21="","",Products!$A$21) | B18: =IF(Products!$A$21="","",SUMIFS('Sales Log'!$C$5:$C$300,'Sales Log'!$B$5:$B$300,Products!$A$21)) | C18: =IF(Products!$A$21="","",SUMIFS('Sales Log'!$F$5:$F$300,'Sales Log'!$B$5:$B$300,Products!$A$21)) | D18: =IF(Products!$A$21="","",SUMIFS('Sales Log'!$G$5:$G$300,'Sales Log'!$B$5:$B$300,Products!$A$21)) | E18: =IF(Products!$A$21="","",SUMIFS('Sales Log'!$H$5:$H$300,'Sales Log'!$B$5:$B$300,Products!$A$21))
A19: =IF(Products!$A$22="","",Products!$A$22) | B19: =IF(Products!$A$22="","",SUMIFS('Sales Log'!$C$5:$C$300,'Sales Log'!$B$5:$B$300,Products!$A$22)) | C19: =IF(Products!$A$22="","",SUMIFS('Sales Log'!$F$5:$F$300,'Sales Log'!$B$5:$B$300,Products!$A$22)) | D19: =IF(Products!$A$22="","",SUMIFS('Sales Log'!$G$5:$G$300,'Sales Log'!$B$5:$B$300,Products!$A$22)) | E19: =IF(Products!$A$22="","",SUMIFS('Sales Log'!$H$5:$H$300,'Sales Log'!$B$5:$B$300,Products!$A$22))
A20: =IF(Products!$A$23="","",Products!$A$23) | B20: =IF(Products!$A$23="","",SUMIFS('Sales Log'!$C$5:$C$300,'Sales Log'!$B$5:$B$300,Products!$A$23)) | C20: =IF(Products!$A$23="","",SUMIFS('Sales Log'!$F$5:$F$300,'Sales Log'!$B$5:$B$300,Products!$A$23)) | D20: =IF(Products!$A$23="","",SUMIFS('Sales Log'!$G$5:$G$300,'Sales Log'!$B$5:$B$300,Products!$A$23)) | E20: =IF(Products!$A$23="","",SUMIFS('Sales Log'!$H$5:$H$300,'Sales Log'!$B$5:$B$300,Products!$A$23))
A21: =IF(Products!$A$24="","",Products!$A$24) | B21: =IF(Products!$A$24="","",SUMIFS('Sales Log'!$C$5:$C$300,'Sales Log'!$B$5:$B$300,Products!$A$24)) | C21: =IF(Products!$A$24="","",SUMIFS('Sales Log'!$F$5:$F$300,'Sales Log'!$B$5:$B$300,Products!$A$24)) | D21: =IF(Products!$A$24="","",SUMIFS('Sales Log'!$G$5:$G$300,'Sales Log'!$B$5:$B$300,Products!$A$24)) | E21: =IF(Products!$A$24="","",SUMIFS('Sales Log'!$H$5:$H$300,'Sales Log'!$B$5:$B$300,Products!$A$24))
A22: =IF(Products!$A$25="","",Products!$A$25) | B22: =IF(Products!$A$25="","",SUMIFS('Sales Log'!$C$5:$C$300,'Sales Log'!$B$5:$B$300,Products!$A$25)) | C22: =IF(Products!$A$25="","",SUMIFS('Sales Log'!$F$5:$F$300,'Sales Log'!$B$5:$B$300,Products!$A$25)) | D22: =IF(Products!$A$25="","",SUMIFS('Sales Log'!$G$5:$G$300,'Sales Log'!$B$5:$B$300,Products!$A$25)) | E22: =IF(Products!$A$25="","",SUMIFS('Sales Log'!$H$5:$H$300,'Sales Log'!$B$5:$B$300,Products!$A$25))
A23: =IF(Products!$A$26="","",Products!$A$26) | B23: =IF(Products!$A$26="","",SUMIFS('Sales Log'!$C$5:$C$300,'Sales Log'!$B$5:$B$300,Products!$A$26)) | C23: =IF(Products!$A$26="","",SUMIFS('Sales Log'!$F$5:$F$300,'Sales Log'!$B$5:$B$300,Products!$A$26)) | D23: =IF(Products!$A$26="","",SUMIFS('Sales Log'!$G$5:$G$300,'Sales Log'!$B$5:$B$300,Products!$A$26)) | E23: =IF(Products!$A$26="","",SUMIFS('Sales Log'!$H$5:$H$300,'Sales Log'!$B$5:$B$300,Products!$A$26))
A24: =IF(Products!$A$27="","",Products!$A$27) | B24: =IF(Products!$A$27="","",SUMIFS('Sales Log'!$C$5:$C$300,'Sales Log'!$B$5:$B$300,Products!$A$27)) | C24: =IF(Products!$A$27="","",SUMIFS('Sales Log'!$F$5:$F$300,'Sales Log'!$B$5:$B$300,Products!$A$27)) | D24: =IF(Products!$A$27="","",SUMIFS('Sales Log'!$G$5:$G$300,'Sales Log'!$B$5:$B$300,Products!$A$27)) | E24: =IF(Products!$A$27="","",SUMIFS('Sales Log'!$H$5:$H$300,'Sales Log'!$B$5:$B$300,Products!$A$27))
A25: =IF(Products!$A$28="","",Products!$A$28) | B25: =IF(Products!$A$28="","",SUMIFS('Sales Log'!$C$5:$C$300,'Sales Log'!$B$5:$B$300,Products!$A$28)) | C25: =IF(Products!$A$28="","",SUMIFS('Sales Log'!$F$5:$F$300,'Sales Log'!$B$5:$B$300,Products!$A$28)) | D25: =IF(Products!$A$28="","",SUMIFS('Sales Log'!$G$5:$G$300,'Sales Log'!$B$5:$B$300,Products!$A$28)) | E25: =IF(Products!$A$28="","",SUMIFS('Sales Log'!$H$5:$H$300,'Sales Log'!$B$5:$B$300,Products!$A$28))
A26: =IF(Products!$A$29="","",Products!$A$29) | B26: =IF(Products!$A$29="","",SUMIFS('Sales Log'!$C$5:$C$300,'Sales Log'!$B$5:$B$300,Products!$A$29)) | C26: =IF(Products!$A$29="","",SUMIFS('Sales Log'!$F$5:$F$300,'Sales Log'!$B$5:$B$300,Products!$A$29)) | D26: =IF(Products!$A$29="","",SUMIFS('Sales Log'!$G$5:$G$300,'Sales Log'!$B$5:$B$300,Products!$A$29)) | E26: =IF(Products!$A$29="","",SUMIFS('Sales Log'!$H$5:$H$300,'Sales Log'!$B$5:$B$300,Products!$A$29))
A27: =IF(Products!$A$30="","",Products!$A$30) | B27: =IF(Products!$A$30="","",SUMIFS('Sales Log'!$C$5:$C$300,'Sales Log'!$B$5:$B$300,Products!$A$30)) | C27: =IF(Products!$A$30="","",SUMIFS('Sales Log'!$F$5:$F$300,'Sales Log'!$B$5:$B$300,Products!$A$30)) | D27: =IF(Products!$A$30="","",SUMIFS('Sales Log'!$G$5:$G$300,'Sales Log'!$B$5:$B$300,Products!$A$30)) | E27: =IF(Products!$A$30="","",SUMIFS('Sales Log'!$H$5:$H$300,'Sales Log'!$B$5:$B$300,Products!$A$30))
A28: =IF(Products!$A$31="","",Products!$A$31) | B28: =IF(Products!$A$31="","",SUMIFS('Sales Log'!$C$5:$C$300,'Sales Log'!$B$5:$B$300,Products!$A$31)) | C28: =IF(Products!$A$31="","",SUMIFS('Sales Log'!$F$5:$F$300,'Sales Log'!$B$5:$B$300,Products!$A$31)) | D28: =IF(Products!$A$31="","",SUMIFS('Sales Log'!$G$5:$G$300,'Sales Log'!$B$5:$B$300,Products!$A$31)) | E28: =IF(Products!$A$31="","",SUMIFS('Sales Log'!$H$5:$H$300,'Sales Log'!$B$5:$B$300,Products!$A$31))
A29: =IF(Products!$A$32="","",Products!$A$32) | B29: =IF(Products!$A$32="","",SUMIFS('Sales Log'!$C$5:$C$300,'Sales Log'!$B$5:$B$300,Products!$A$32)) | C29: =IF(Products!$A$32="","",SUMIFS('Sales Log'!$F$5:$F$300,'Sales Log'!$B$5:$B$300,Products!$A$32)) | D29: =IF(Products!$A$32="","",SUMIFS('Sales Log'!$G$5:$G$300,'Sales Log'!$B$5:$B$300,Products!$A$32)) | E29: =IF(Products!$A$32="","",SUMIFS('Sales Log'!$H$5:$H$300,'Sales Log'!$B$5:$B$300,Products!$A$32))
A30: =IF(Products!$A$33="","",Products!$A$33) | B30: =IF(Products!$A$33="","",SUMIFS('Sales Log'!$C$5:$C$300,'Sales Log'!$B$5:$B$300,Products!$A$33)) | C30: =IF(Products!$A$33="","",SUMIFS('Sales Log'!$F$5:$F$300,'Sales Log'!$B$5:$B$300,Products!$A$33)) | D30: =IF(Products!$A$33="","",SUMIFS('Sales Log'!$G$5:$G$300,'Sales Log'!$B$5:$B$300,Products!$A$33)) | E30: =IF(Products!$A$33="","",SUMIFS('Sales Log'!$H$5:$H$300,'Sales Log'!$B$5:$B$300,Products!$A$33))
A31: =IF(Products!$A$34="","",Products!$A$34) | B31: =IF(Products!$A$34="","",SUMIFS('Sales Log'!$C$5:$C$300,'Sales Log'!$B$5:$B$300,Products!$A$34)) | C31: =IF(Products!$A$34="","",SUMIFS('Sales Log'!$F$5:$F$300,'Sales Log'!$B$5:$B$300,Products!$A$34)) | D31: =IF(Products!$A$34="","",SUMIFS('Sales Log'!$G$5:$G$300,'Sales Log'!$B$5:$B$300,Products!$A$34)) | E31: =IF(Products!$A$34="","",SUMIFS('Sales Log'!$H$5:$H$300,'Sales Log'!$B$5:$B$300,Products!$A$34))
A32: =IF(Products!$A$35="","",Products!$A$35) | B32: =IF(Products!$A$35="","",SUMIFS('Sales Log'!$C$5:$C$300,'Sales Log'!$B$5:$B$300,Products!$A$35)) | C32: =IF(Products!$A$35="","",SUMIFS('Sales Log'!$F$5:$F$300,'Sales Log'!$B$5:$B$300,Products!$A$35)) | D32: =IF(Products!$A$35="","",SUMIFS('Sales Log'!$G$5:$G$300,'Sales Log'!$B$5:$B$300,Products!$A$35)) | E32: =IF(Products!$A$35="","",SUMIFS('Sales Log'!$H$5:$H$300,'Sales Log'!$B$5:$B$300,Products!$A$35))
A33: =IF(Products!$A$36="","",Products!$A$36) | B33: =IF(Products!$A$36="","",SUMIFS('Sales Log'!$C$5:$C$300,'Sales Log'!$B$5:$B$300,Products!$A$36)) | C33: =IF(Products!$A$36="","",SUMIFS('Sales Log'!$F$5:$F$300,'Sales Log'!$B$5:$B$300,Products!$A$36)) | D33: =IF(Products!$A$36="","",SUMIFS('Sales Log'!$G$5:$G$300,'Sales Log'!$B$5:$B$300,Products!$A$36)) | E33: =IF(Products!$A$36="","",SUMIFS('Sales Log'!$H$5:$H$300,'Sales Log'!$B$5:$B$300,Products!$A$36))
A34: =IF(Products!$A$37="","",Products!$A$37) | B34: =IF(Products!$A$37="","",SUMIFS('Sales Log'!$C$5:$C$300,'Sales Log'!$B$5:$B$300,Products!$A$37)) | C34: =IF(Products!$A$37="","",SUMIFS('Sales Log'!$F$5:$F$300,'Sales Log'!$B$5:$B$300,Products!$A$37)) | D34: =IF(Products!$A$37="","",SUMIFS('Sales Log'!$G$5:$G$300,'Sales Log'!$B$5:$B$300,Products!$A$37)) | E34: =IF(Products!$A$37="","",SUMIFS('Sales Log'!$H$5:$H$300,'Sales Log'!$B$5:$B$300,Products!$A$37))
A35: =IF(Products!$A$38="","",Products!$A$38) | B35: =IF(Products!$A$38="","",SUMIFS('Sales Log'!$C$5:$C$300,'Sales Log'!$B$5:$B$300,Products!$A$38)) | C35: =IF(Products!$A$38="","",SUMIFS('Sales Log'!$F$5:$F$300,'Sales Log'!$B$5:$B$300,Products!$A$38)) | D35: =IF(Products!$A$38="","",SUMIFS('Sales Log'!$G$5:$G$300,'Sales Log'!$B$5:$B$300,Products!$A$38)) | E35: =IF(Products!$A$38="","",SUMIFS('Sales Log'!$H$5:$H$300,'Sales Log'!$B$5:$B$300,Products!$A$38))
A36: =IF(Products!$A$39="","",Products!$A$39) | B36: =IF(Products!$A$39="","",SUMIFS('Sales Log'!$C$5:$C$300,'Sales Log'!$B$5:$B$300,Products!$A$39)) | C36: =IF(Products!$A$39="","",SUMIFS('Sales Log'!$F$5:$F$300,'Sales Log'!$B$5:$B$300,Products!$A$39)) | D36: =IF(Products!$A$39="","",SUMIFS('Sales Log'!$G$5:$G$300,'Sales Log'!$B$5:$B$300,Products!$A$39)) | E36: =IF(Products!$A$39="","",SUMIFS('Sales Log'!$H$5:$H$300,'Sales Log'!$B$5:$B$300,Products!$A$39))
A37: =IF(Products!$A$40="","",Products!$A$40) | B37: =IF(Products!$A$40="","",SUMIFS('Sales Log'!$C$5:$C$300,'Sales Log'!$B$5:$B$300,Products!$A$40)) | C37: =IF(Products!$A$40="","",SUMIFS('Sales Log'!$F$5:$F$300,'Sales Log'!$B$5:$B$300,Products!$A$40)) | D37: =IF(Products!$A$40="","",SUMIFS('Sales Log'!$G$5:$G$300,'Sales Log'!$B$5:$B$300,Products!$A$40)) | E37: =IF(Products!$A$40="","",SUMIFS('Sales Log'!$H$5:$H$300,'Sales Log'!$B$5:$B$300,Products!$A$40))
A38: =IF(Products!$A$41="","",Products!$A$41) | B38: =IF(Products!$A$41="","",SUMIFS('Sales Log'!$C$5:$C$300,'Sales Log'!$B$5:$B$300,Products!$A$41)) | C38: =IF(Products!$A$41="","",SUMIFS('Sales Log'!$F$5:$F$300,'Sales Log'!$B$5:$B$300,Products!$A$41)) | D38: =IF(Products!$A$41="","",SUMIFS('Sales Log'!$G$5:$G$300,'Sales Log'!$B$5:$B$300,Products!$A$41)) | E38: =IF(Products!$A$41="","",SUMIFS('Sales Log'!$H$5:$H$300,'Sales Log'!$B$5:$B$300,Products!$A$41))
A39: =IF(Products!$A$42="","",Products!$A$42) | B39: =IF(Products!$A$42="","",SUMIFS('Sales Log'!$C$5:$C$300,'Sales Log'!$B$5:$B$300,Products!$A$42)) | C39: =IF(Products!$A$42="","",SUMIFS('Sales Log'!$F$5:$F$300,'Sales Log'!$B$5:$B$300,Products!$A$42)) | D39: =IF(Products!$A$42="","",SUMIFS('Sales Log'!$G$5:$G$300,'Sales Log'!$B$5:$B$300,Products!$A$42)) | E39: =IF(Products!$A$42="","",SUMIFS('Sales Log'!$H$5:$H$300,'Sales Log'!$B$5:$B$300,Products!$A$42))
A40: =IF(Products!$A$43="","",Products!$A$43) | B40: =IF(Products!$A$43="","",SUMIFS('Sales Log'!$C$5:$C$300,'Sales Log'!$B$5:$B$300,Products!$A$43)) | C40: =IF(Products!$A$43="","",SUMIFS('Sales Log'!$F$5:$F$300,'Sales Log'!$B$5:$B$300,Products!$A$43)) | D40: =IF(Products!$A$43="","",SUMIFS('Sales Log'!$G$5:$G$300,'Sales Log'!$B$5:$B$300,Products!$A$43)) | E40: =IF(Products!$A$43="","",SUMIFS('Sales Log'!$H$5:$H$300,'Sales Log'!$B$5:$B$300,Products!$A$43))
A41: =IF(Products!$A$44="","",Products!$A$44) | B41: =IF(Products!$A$44="","",SUMIFS('Sales Log'!$C$5:$C$300,'Sales Log'!$B$5:$B$300,Products!$A$44)) | C41: =IF(Products!$A$44="","",SUMIFS('Sales Log'!$F$5:$F$300,'Sales Log'!$B$5:$B$300,Products!$A$44)) | D41: =IF(Products!$A$44="","",SUMIFS('Sales Log'!$G$5:$G$300,'Sales Log'!$B$5:$B$300,Products!$A$44)) | E41: =IF(Products!$A$44="","",SUMIFS('Sales Log'!$H$5:$H$300,'Sales Log'!$B$5:$B$300,Products!$A$44))
A42: =IF(Products!$A$45="","",Products!$A$45) | B42: =IF(Products!$A$45="","",SUMIFS('Sales Log'!$C$5:$C$300,'Sales Log'!$B$5:$B$300,Products!$A$45)) | C42: =IF(Products!$A$45="","",SUMIFS('Sales Log'!$F$5:$F$300,'Sales Log'!$B$5:$B$300,Products!$A$45)) | D42: =IF(Products!$A$45="","",SUMIFS('Sales Log'!$G$5:$G$300,'Sales Log'!$B$5:$B$300,Products!$A$45)) | E42: =IF(Products!$A$45="","",SUMIFS('Sales Log'!$H$5:$H$300,'Sales Log'!$B$5:$B$300,Products!$A$45))
A43: =IF(Products!$A$46="","",Products!$A$46) | B43: =IF(Products!$A$46="","",SUMIFS('Sales Log'!$C$5:$C$300,'Sales Log'!$B$5:$B$300,Products!$A$46)) | C43: =IF(Products!$A$46="","",SUMIFS('Sales Log'!$F$5:$F$300,'Sales Log'!$B$5:$B$300,Products!$A$46)) | D43: =IF(Products!$A$46="","",SUMIFS('Sales Log'!$G$5:$G$300,'Sales Log'!$B$5:$B$300,Products!$A$46)) | E43: =IF(Products!$A$46="","",SUMIFS('Sales Log'!$H$5:$H$300,'Sales Log'!$B$5:$B$300,Products!$A$46))
...
